Workbook

Sheet Assumptions
E1: Year 2002 | F1: Year 2024 | G1: Year 2025 | S1: Year 2025 | T1: Year 2050 | U1: Year 2 | W1: Year 3 | X1: Year 4 | Y1: Year 5
A2: Macro assumptions | B2: Forecast Basis | C2: Variable calcultation | D2: Static assumptions | F2: Ending Pop | G2: 1 | H2: 2 | I2: 3 | J2: 4 | K2: 5 | L2: 6 | M2: 7 | N2: 8 | O2: 9 | P2: 10 | Q2: 11 | R2: 12 | S2: Ending Pop | T2: Total | U2: First 6 months | V2: Second 6 months
A3: Individuals
A4: Population | B4: Annual Growth rate - average taken of 48 yrs 2002-2050 | C4: =((T5-E5)/E5)*1/48*100 -> 0.5134279
A5: Population | B5: Monthly Growth rate | C5: =((1+C4)^(1/12)-1)/100 -> 0.00035134567 | D5: https://data.london.gov.uk/dataset/trend-based-population-projections | E5: 1.6253655e+08 | F5: 1.8912624e+08 | G5: =F5*(1+$C$5) -> 1.8919269e+08 | H5: =G5*(1+$C$5) -> 1.8925916e+08 | I5: =H5*(1+$C$5) -> 1.8932566e+08 | J5: =I5*(1+$C$5) -> 1.8939217e+08 | K5: =J5*(1+$C$5) -> 1.8945872e+08 | L5: =K5*(1+$C$5) -> 1.8952528e+08 | M5: =L5*(1+$C$5) -> 1.8959187e+08 | N5: =M5*(1+$C$5) -> 1.8965848e+08 | ... R5: =Q5*(1+$C$5) -> 1.8992517e+08 | S5: 1.8985368e+08 | T5: 2.0259293e+08 | U5: 4500 | V5: 4500 | W5: 5000 | X5: 5500 | Y5: 6000
A6: Target Demographics (18-40) | B6: Target demogrpahics make on avg 30% of total pop (avg taken of 48 years 2002-2050) | C6: 0.3 | D6: https://data.london.gov.uk/dataset/trend-based-population-projections | G6: =G5*$C$6 -> 56757807 | H6: =H5*$C$6 -> 56777748 | I6: =I5*$C$6 -> 56797697 | J6: =J5*$C$6 -> 56817652 | K6: =K5*$C$6 -> 56837615 | L6: =L5*$C$6 -> 56857585 | M6: =M5*$C$6 -> 56877561 | N6: =N5*$C$6 -> 56897545 | ... R6: =R5*$C$6 -> 56977550 | U6: 0.7 | V6: 0.72 | W6: 0.74 | X6: 0.73 | Y6: 0.75
A7: Tech-Savy Users | B7: 60% of target demographic is comfortable using fintech apps | C7: 0.6 | D7: Need to deep dive | G7: =G6*$C$7 -> 34054684 | H7: =H6*$C$7 -> 34066649 | I7: =I6*$C$7 -> 34078618 | J7: =J6*$C$7 -> 34090591 | K7: =K6*$C$7 -> 34102569 | L7: =L6*$C$7 -> 34114551 | M7: =M6*$C$7 -> 34126537 | N7: =N6*$C$7 -> 34138527 | ... R7: =R6*$C$7 -> 34186530
A8: Bank Account holders | B8: 80% of the tech savy users have a bank account | C8: 0.8 | D8: Need to deep dive | G8: =G7*$C$8 -> 27243747 | H8: =H7*$C$8 -> 27253319 | I8: =I7*$C$8 -> 27262894 | J8: =J7*$C$8 -> 27272473 | K8: =K7*$C$8 -> 27282055 | L8: =L7*$C$8 -> 27291641 | M8: =M7*$C$8 -> 27301229 | N8: =N7*$C$8 -> 27310822 | ... R8: =R7*$C$8 -> 27349224 | U8: 116 | V8: 116 | W8: 232 | X8: 234 | Y8: 231
A9: Individuals target in first year | B9: Monthly growth rate to reach 40500 individuals by the end of first year | C9: 0.3305 | D9: 40500- expected by the sales teams of USI | G9: 450 | H9: =G9*(1+$C$9) -> 598.725 | I9: =H9*(1+$C$9) -> 796.60361 | J9: =I9*(1+$C$9) -> 1059.8811 | K9: =J9*(1+$C$9) -> 1410.1718 | L9: =K9*(1+$C$9) -> 1876.2336 | M9: =L9*(1+$C$9) -> 2496.3288 | N9: =M9*(1+$C$9) -> 3321.3655 | O9: =N9*(1+$C$9) -> 4419.0768 | ... R9: =Q9*(1+$C$9) -> 10408.213
A10: Total Cumulative Individuals p/m | G10: =G9 -> 450 | H10: =G10+H9 -> 1048.725 | I10: =H10+I9 -> 1845.3286 | J10: =I10+J9 -> 2905.2097 | K10: =J10+K9 -> 4315.3815 | L10: =K10+L9 -> 6191.6151 | M10: =L10+M9 -> 8687.9439 | N10: =M10+N9 -> 12009.309 | O10: =N10+O9 -> 16428.386 | ... R10: =Q10+R9 -> 40538.964
A11: No of active cards | B11: assuming active rate of 65% | C11: 0.65 | D11: cards active p/m | G11: =G10*$C$11 -> 292.5 | H11: =H10*$C$11 -> 681.67125 | I11: =I10*$C$11 -> 1199.4636 | J11: =J10*$C$11 -> 1888.3863 | K11: =K10*$C$11 -> 2804.998 | L11: =L10*$C$11 -> 4024.5498 | M11: =M10*$C$11 -> 5647.1636 | N11: =N10*$C$11 -> 7806.0511 | ... R11: =R10*$C$11 -> 26350.327 | S11: =S9*$C$11 -> 0 | T11: =T9*$C$11 -> 0
A12: No of transactions | B12: Assuming individual makes 5 transactions per month | C12: 5 | D12: (fx, online, internal transfer- everything) | G12: =$C$12*G11 -> 1462.5 | H12: =$C$12*H11 -> 3408.3562 | I12: =$C$12*I11 -> 5997.318 | J12: =$C$12*J11 -> 9441.9316 | K12: =$C$12*K11 -> 14024.99 | L12: =$C$12*L11 -> 20122.749 | M12: =$C$12*M11 -> 28235.818 | N12: =$C$12*N11 -> 39030.256 | ... R12: =$C$12*R11 -> 131751.63
A13: No of Physical Cards requested | B13: Individuals using physical cards to make payments | C13: 0.2 | D13: assuming 20% go for physical cards | F13: might incorporate payment plans | G13: =$C$13*G9 -> 90 | H13: =$C$13*H9 -> 119.745 | I13: =$C$13*I9 -> 159.32072 | J13: =$C$13*J9 -> 211.97622 | K13: =$C$13*K9 -> 282.03436 | L13: =$C$13*L9 -> 375.24672 | M13: =$C$13*M9 -> 499.26576 | N13: =$C$13*N9 -> 664.27309 | ... R13: =$C$13*R9 -> 2081.6426
A14: No of cards push thru | B14: Individuals using electronic pay(Google/apple pay) | C14: 0.8 | D14: assuming 80% will go for google/apple pay | G14: =G9*$C$14 -> 360 | H14: =H9*$C$14 -> 478.98 | I14: =I9*$C$14 -> 637.28289 | J14: =J9*$C$14 -> 847.90489 | K14: =K9*$C$14 -> 1128.1374 | L14: =L9*$C$14 -> 1500.9869 | M14: =M9*$C$14 -> 1997.063 | N14: =N9*$C$14 -> 2657.0924 | ... R14: =R9*$C$14 -> 8326.5706
A15: No of transactions via ATM withdrawals | B15: 20% of total transaction pertains to this | C15: 0.2 | D15: assuming we charge 1% of amount withdrawn | F15: 1 | G15: =$C$15*G12 -> 292.5 | H15: =$C$15*H12 -> 681.67125 | I15: =$C$15*I12 -> 1199.4636 | J15: =$C$15*J12 -> 1888.3863 | K15: =$C$15*K12 -> 2804.998 | L15: =$C$15*L12 -> 4024.5498 | M15: =$C$15*M12 -> 5647.1636 | N15: =$C$15*N12 -> 7806.0511 | ... R15: =$C$15*R12 -> 26350.327
A16: No of transactions via push pay | B16: 40% of total transaction per tains to this | C16: 0.4 | D16: anyone using E-pay to make payment | F16: 2 | G16: =$C$16*G12 -> 585 | H16: =$C$16*H12 -> 1363.3425 | I16: =$C$16*I12 -> 2398.9272 | J16: =$C$16*J12 -> 3776.7726 | K16: =$C$16*K12 -> 5609.996 | L16: =$C$16*L12 -> 8049.0997 | M16: =$C$16*M12 -> 11294.327 | N16: =$C$16*N12 -> 15612.102 | ... R16: =$C$16*R12 -> 52700.654
A17: No of transactions using FX | B17: 20% of total transaction pertains to this | C17: 0.2 | D17: any foreign currency transaction made | F17: 1 | G17: =$C$17*G12 -> 292.5 | H17: =$C$17*H12 -> 681.67125 | I17: =$C$17*I12 -> 1199.4636 | J17: =$C$17*J12 -> 1888.3863 | K17: =$C$17*K12 -> 2804.998 | L17: =$C$17*L12 -> 4024.5498 | M17: =$C$17*M12 -> 5647.1636 | N17: =$C$17*N12 -> 7806.0511 | ... R17: =$C$17*R12 -> 26350.327
A18: No of OTP/SDS transactions | B18: 20% of total transaction pertains to this | C18: 0.2 | D18: any online payment made via OTP | F18: 1 | G18: =$C$18*G12 -> 292.5 | H18: =$C$18*H12 -> 681.67125 | I18: =$C$18*I12 -> 1199.4636 | J18: =$C$18*J12 -> 1888.3863 | K18: =$C$18*K12 -> 2804.998 | L18: =$C$18*L12 -> 4024.5498 | M18: =$C$18*M12 -> 5647.1636 | N18: =$C$18*N12 -> 7806.0511 | ... R18: =$C$18*R12 -> 26350.327
A19: No of times user checks their card info | B19: assuming 6 times a month | C19: 6 | D19: copying card details | G19: =$C$19*G14 -> 2160 | H19: =($C$19*H14)+G19 -> 5033.88 | I19: =($C$19*I14)+H19 -> 8857.5773 | J19: =($C$19*J14)+I19 -> 13945.007 | K19: =($C$19*K14)+J19 -> 20713.831 | L19: =($C$19*L14)+K19 -> 29719.753 | M19: =($C$19*M14)+L19 -> 41702.131 | N19: =($C$19*N14)+M19 -> 57644.685 | O19: =($C$19*O14)+N19 -> 78856.254 | ... R19: =($C$19*R14)+Q19 -> 194587.03 | S19: =$C$19*S14 -> 0 | T19: =$C$19*T14 -> 0
B21: charges on atm withdrawal/fx | F21: limit atm withdrawal- upto two free
A22: Businesses
A23: Population | B23: ='Business Pop'!A63 -> Monthly Growth rate | C23: ='Business Pop'!B63/100 -> 0.00085011032 | D23: https://www.ons.gov.uk/businessindustryandtrade/business/activitysizeandlocation/adhocs/1136smebyregionandindustry | G23: ='Business Pop'!$R$35*(1+$C$23) -> 2727086.4 | H23: =G23*(1+$C$23) -> 2729404.7 | I23: =H23*(1+$C$23) -> 2731725 | J23: =I23*(1+$C$23) -> 2734047.2 | K23: =J23*(1+$C$23) -> 2736371.5 | L23: =K23*(1+$C$23) -> 2738697.7 | M23: =L23*(1+$C$23) -> 2741025.9 | N23: =M23*(1+$C$23) -> 2743356.1 | O23: =N23*(1+$C$23) -> 2745688.2 | ... R23: =Q23*(1+$C$23) -> 2752696.6
A24: SMEs | B24: employee count>250 | G24: =SUM('Business Pop'!$C$65:$E$65)*Assumptions!G23 -> 1802404.2 | H24: =SUM('Business Pop'!$C$65:$E$65)*Assumptions!H23 -> 1803936.5 | I24: =SUM('Business Pop'!$C$65:$E$65)*Assumptions!I23 -> 1805470 | J24: =SUM('Business Pop'!$C$65:$E$65)*Assumptions!J23 -> 1807004.9 | K24: =SUM('Business Pop'!$C$65:$E$65)*Assumptions!K23 -> 1808541 | L24: =SUM('Business Pop'!$C$65:$E$65)*Assumptions!L23 -> 1810078.5 | M24: =SUM('Business Pop'!$C$65:$E$65)*Assumptions!M23 -> 1811617.3 | N24: =SUM('Business Pop'!$C$65:$E$65)*Assumptions!N23 -> 1813157.3 | ... R24: =SUM('Business Pop'!$C$65:$E$65)*Assumptions!R23 -> 1819330.7
A25: Enterprises based on legal status | B25: Sole proprietor, partnerships & Non profit body | C25: ='Business Pop'!B69 -> 0.17817467 | D25: % of legel status compared to total pop | G25: =$C$25*G23 -> 485897.72 | H25: =$C$25*H23 -> 486310.78 | I25: =$C$25*I23 -> 486724.2 | J25: =$C$25*J23 -> 487137.97 | K25: =$C$25*K23 -> 487552.09 | L25: =$C$25*L23 -> 487966.56 | M25: =$C$25*M23 -> 488381.39 | N25: =$C$25*N23 -> 488796.57 | ... R25: =$C$25*R23 -> 490460.81
A26: SMEs based on legal status | C26: =SUM('Business Pop'!$C$68:$E$68)/'Business Pop'!M68 -> 0.76777861 | G26: =G25*$C$26 -> 373061.87 | H26: =H25*$C$26 -> 373379.02 | I26: =I25*$C$26 -> 373696.43 | J26: =J25*$C$26 -> 374014.11 | K26: =K25*$C$26 -> 374332.07 | L26: =L25*$C$26 -> 374650.29 | M26: =M25*$C$26 -> 374968.79 | N26: =N25*$C$26 -> 375287.55 | ... R26: =R25*$C$26 -> 376565.32
A27: % tech savy businesses | C27: 0.7 | D27: Need to deep dive | G27: =G26*$C$27 -> 261143.31 | H27: =H26*$C$27 -> 261365.31 | I27: =I26*$C$27 -> 261587.5 | J27: =J26*$C$27 -> 261809.88 | K27: =K26*$C$27 -> 262032.45 | L27: =L26*$C$27 -> 262255.2 | M27: =M26*$C$27 -> 262478.15 | N27: =N26*$C$27 -> 262701.29 | ... R27: =R26*$C$27 -> 263595.73
A28: % businesses requiring EMI services | C28: 0.3 | D28: Need to deep dive | G28: =$C$28*G27 -> 78342.994 | H28: =$C$28*H27 -> 78409.594 | I28: =$C$28*I27 -> 78476.251 | J28: =$C$28*J27 -> 78542.964 | K28: =$C$28*K27 -> 78609.734 | L28: =$C$28*L27 -> 78676.561 | M28: =$C$28*M27 -> 78743.445 | N28: =$C$28*N27 -> 78810.386 | ... R28: =$C$28*R27 -> 79078.718
A29: New Businesses target in first year | B29: Monthly growth rate to reach 4500 businesses by the end of first year | C29: =C9 -> 0.3305 | D29: 4500-expected by the sales team of USI | F29: incorporate 500 more take the number to 5k | G29: 50 | H29: =G29*(1+$C$29) -> 66.525 | I29: =H29*(1+$C$29) -> 88.511513 | J29: =I29*(1+$C$29) -> 117.76457 | K29: =J29*(1+$C$29) -> 156.68576 | L29: =K29*(1+$C$29) -> 208.4704 | M29: =L29*(1+$C$29) -> 277.36987 | N29: =M29*(1+$C$29) -> 369.04061 | O29: =N29*(1+$C$29) -> 491.00853 | ... R29: =Q29*(1+$C$29) -> 1156.4681
A30: Current customer base added | B30: USI's current customer base added | C30: 350 | G30: 350 | H30: 0 | I30: 0 | J30: 0 | K30: 0 | L30: 0 | M30: 0 | N30: 0 | O30: 0 | P30: 0 | Q30: 0 | R30: 0
A31: Total customers expected | G31: =G29+G30 -> 400 | H31: =H29+H30 -> 66.525 | I31: =I29+I30 -> 88.511513 | J31: =J29+J30 -> 117.76457 | K31: =K29+K30 -> 156.68576 | L31: =L29+L30 -> 208.4704 | M31: =M29+M30 -> 277.36987 | N31: =N29+N30 -> 369.04061 | ... T31: =T29+T30 -> 0
A32: Total Cumulative customers p/m | G32: =G31 -> 400 | H32: =G32+H31 -> 466.525 | I32: =H32+I31 -> 555.03651 | J32: =I32+J31 -> 672.80108 | K32: =J32+K31 -> 829.48684 | L32: =K32+L31 -> 1037.9572 | M32: =L32+M31 -> 1315.3271 | N32: =M32+N31 -> 1684.3677 | O32: =N32+O31 -> 2175.3762 | ... R32: =Q32+R31 -> 4854.3294
A33: No of active cards | B33: assuming active rate of 65% | C33: 0.65 | D33: cards active p/m | G33: =G32*$C$33 -> 260 | H33: =H32*$C$33 -> 303.24125 | I33: =I32*$C$33 -> 360.77373 | J33: =J32*$C$33 -> 437.3207 | K33: =K32*$C$33 -> 539.16644 | L33: =L32*$C$33 -> 674.6722 | M33: =M32*$C$33 -> 854.96262 | N33: =N32*$C$33 -> 1094.839 | ... R33: =R32*$C$33 -> 3155.3141
A34: No of transactions | B34: Assuming businesses makes 10 transactions per month | C34: 10 | D34: (fx, online, internal transfer- everything) | G34: =$C$34*G33 -> 2600 | H34: =$C$34*H33 -> 3032.4125 | I34: =$C$34*I33 -> 3607.7373 | J34: =$C$34*J33 -> 4373.207 | K34: =$C$34*K33 -> 5391.6644 | L34: =$C$34*L33 -> 6746.722 | M34: =$C$34*M33 -> 8549.6262 | N34: =$C$34*N33 -> 10948.39 | ... R34: =$C$34*R33 -> 31553.141
A35: No of Physical Cards requested | B35: assuming 80% of new business customers go for physical cards | C35: 0.8 | D35: requesting 3 cards/business | F35: 3 | G35: =$C$35*G31*$F$35 -> 960 | H35: =$C$35*H31*$F$35 -> 159.66 | I35: =$C$35*I31*$F$35 -> 212.42763 | J35: =$C$35*J31*$F$35 -> 282.63496 | K35: =$C$35*K31*$F$35 -> 376.04582 | L35: =$C$35*L31*$F$35 -> 500.32896 | M35: =$C$35*M31*$F$35 -> 665.68768 | N35: =$C$35*N31*$F$35 -> 885.69746 | ... R35: =$C$35*R31*$F$35 -> 2775.5235 | S35: =$C$35*S33*$F$35 -> 0 | T35: =$C$35*T33*$F$35 -> 0
A36: No of cards push thru | B36: assuming 20% of new business customers gor for electronic cards | C36: 0.2 | D36: assuming 80% will go for google/apple pay | G36: =$C$36*G31 -> 80 | H36: =$C$36*H31 -> 13.305 | I36: =$C$36*I31 -> 17.702303 | J36: =$C$36*J31 -> 23.552913 | K36: =$C$36*K31 -> 31.337151 | L36: =$C$36*L31 -> 41.69408 | M36: =$C$36*M31 -> 55.473973 | N36: =$C$36*N31 -> 73.808122 | ... R36: =$C$36*R31 -> 231.29363
A37: No of transactions via ATM withdrawals | B37: 20% of total transaction pertains to this | C37: 0.2 | D37: assuming we charge 1% of amount withdrawn | F37: 2 | G37: =$C$37*G34 -> 520 | H37: =$C$37*H34 -> 606.4825 | I37: =$C$37*I34 -> 721.54747 | J37: =$C$37*J34 -> 874.6414 | K37: =$C$37*K34 -> 1078.3329 | L37: =$C$37*L34 -> 1349.3444 | M37: =$C$37*M34 -> 1709.9252 | N37: =$C$37*N34 -> 2189.678 | ... T37: =$C$37*T34 -> 0
A38: No of transactions via push pay | B38: 20% of total transaction per tains to this | C38: 0.2 | D38: anyone using E-pay to make payment | F38: 2 | G38: =$C38*G$34 -> 520 | H38: =$C38*H$34 -> 606.4825 | I38: =$C38*I$34 -> 721.54747 | J38: =$C38*J$34 -> 874.6414 | K38: =$C38*K$34 -> 1078.3329 | L38: =$C38*L$34 -> 1349.3444 | M38: =$C38*M$34 -> 1709.9252 | N38: =$C38*N$34 -> 2189.678 | ... T38: =$C38*T$34 -> 0
A39: No of transactions using FX | B39: 20% of total transaction pertains to this | C39: 0.2 | D39: any foreign currency transaction made | F39: 2 | G39: =$C39*G$34 -> 520 | H39: =$C39*H$34 -> 606.4825 | I39: =$C39*I$34 -> 721.54747 | J39: =$C39*J$34 -> 874.6414 | K39: =$C39*K$34 -> 1078.3329 | L39: =$C39*L$34 -> 1349.3444 | M39: =$C39*M$34 -> 1709.9252 | N39: =$C39*N$34 -> 2189.678 | ... R39: =$C39*R$34 -> 6310.6282
A40: No of OTP/SDS transactions | B40: 20% of total transaction pertains to this | C40: 0.2 | D40: any online payment made via OTP | F40: 2 | G40: =$C40*G$34 -> 520 | H40: =$C40*H$34 -> 606.4825 | I40: =$C40*I$34 -> 721.54747 | J40: =$C40*J$34 -> 874.6414 | K40: =$C40*K$34 -> 1078.3329 | L40: =$C40*L$34 -> 1349.3444 | M40: =$C40*M$34 -> 1709.9252 | N40: =$C40*N$34 -> 2189.678 | ... R40: =$C40*R$34 -> 6310.6282
A41: No of other transactions (Chaps + others) | B41: 20% of total transaction pertains to this | C41: 0.2 | D41: any other type of transaction | F41: 2 | G41: =$C$41*G34 -> 520 | H41: =$C$41*H34 -> 606.4825 | I41: =$C$41*I34 -> 721.54747 | J41: =$C$41*J34 -> 874.6414 | K41: =$C$41*K34 -> 1078.3329 | L41: =$C$41*L34 -> 1349.3444 | M41: =$C$41*M34 -> 1709.9252 | N41: =$C$41*N34 -> 2189.678 | ... R41: =$C$41*R34 -> 6310.6282
...

Sheet Income Statement (Margins)
C1: Year 2025
A2: Title | B2: 0 | C2: 1 | D2: 2 | E2: 3 | F2: 4 | G2: 5 | H2: 6 | I2: 7 | J2: 8 | K2: 9 | L2: 10 | M2: 11 | N2: 12
A4: Sales | C4: =SUM(Assumptions!G125:G140) -> 16398.75 | D4: =SUM(Assumptions!H125:H140) -> 18095.962 | E4: =SUM(Assumptions!I125:I140) -> 22216.802 | F4: =SUM(Assumptions!J125:J140) -> 27699.58 | G4: =SUM(Assumptions!K125:K140) -> 34994.417 | H4: =SUM(Assumptions!L125:L140) -> 44700.196 | I4: =SUM(Assumptions!M125:M140) -> 57613.736 | J4: =SUM(Assumptions!N125:N140) -> 74795.201 | ... N4: =SUM(Assumptions!R125:R140) -> 222148.17
A6: Expenses
A7: Fixed Costs | C7: =SUM(Assumptions!G93:G98) -> 17250 | D7: =SUM(Assumptions!H93:H98) -> 17250 | E7: =SUM(Assumptions!I93:I98) -> 17250 | F7: =SUM(Assumptions!J93:J98) -> 17250 | G7: =SUM(Assumptions!K93:K98) -> 17250 | H7: =SUM(Assumptions!L93:L98) -> 17250 | I7: =SUM(Assumptions!M93:M98) -> 17250 | J7: =SUM(Assumptions!N93:N98) -> 17250 | ... N7: =SUM(Assumptions!R93:R98) -> 17250
A8: Variable Costs | C8: =SUM(Assumptions!G102:G115) -> 4020.475 | D8: =SUM(Assumptions!H102:H115) -> 3147.2015 | E8: =SUM(Assumptions!I102:I115) -> 4271.7753 | F8: =SUM(Assumptions!J102:J115) -> 5768.0207 | G8: =SUM(Assumptions!K102:K115) -> 7758.7753 | H8: =SUM(Assumptions!L102:L115) -> 10407.474 | I8: =SUM(Assumptions!M102:M115) -> 13931.568 | J8: =SUM(Assumptions!N102:N115) -> 18620.375 | ... N8: =SUM(Assumptions!R102:R115) -> 58895.993
A9: Set up costs | C9: =Assumptions!G90 -> 16166.667 | D9: =Assumptions!H90 -> 16166.667 | E9: =Assumptions!I90 -> 16166.667 | F9: =Assumptions!J90 -> 16166.667 | G9: =Assumptions!K90 -> 16166.667 | H9: =Assumptions!L90 -> 16166.667 | I9: =Assumptions!M90 -> 16166.667 | J9: =Assumptions!N90 -> 16166.667 | ... N9: =Assumptions!R90 -> 16166.667
A11: Total cost | C11: =SUM(C7:C9) -> 37437.142 | D11: =SUM(D7:D9) -> 36563.868 | E11: =SUM(E7:E9) -> 37688.442 | F11: =SUM(F7:F9) -> 39184.687 | G11: =SUM(G7:G9) -> 41175.442 | H11: =SUM(H7:H9) -> 43824.141 | I11: =SUM(I7:I9) -> 47348.235 | J11: =SUM(J7:J9) -> 52037.042 | ... N11: =SUM(N7:N9) -> 92312.66
A13: Profit/(loss) | C13: =C4-C11 -> -21038.392 | D13: =D4-D11 -> -18467.906 | E13: =E4-E11 -> -15471.64 | F13: =F4-F11 -> -11485.107 | G13: =G4-G11 -> -6181.0252 | H13: =H4-H11 -> 876.05557 | I13: =I4-I11 -> 10265.502 | J13: =J4-J11 -> 22758.159 | ... N13: =N4-N11 -> 129835.51

Sheet Business Pop
A1: https://www.ons.gov.uk/businessindustryandtrade/business/activitysizeandlocation/adhocs/1136smebyregionandindustry
A4: Table 28 - Number of VAT and/or PAYE based enterprises by broad industry group [note 1] [note 2] [note 3] [note 6] [note 7]
A5: This worksheet contains one table
A6: Units: Counts (control rounded to base 5)
B7: Years
C8: 2009 | D8: 2010 | E8: 2011 | F8: 2012 | G8: 2013 | H8: 2014 | I8: 2015 | J8: 2016 | K8: 2017 | L8: 2018 | M8: 2019 | N8: 2020 | O8: 2021 | P8: 2022 | Q8: 2023 | R8: 2024
A10: Agriculture, forestry & fishing | C10: 139100 | D10: 137135 | E10: 139070 | F10: 138925 | G10: 143855 | H10: 145280 | I10: 146905 | J10: 147600 | K10: 147795 | L10: 149165 | M10: 149540 | N10: 148845 | O10: 141030 | P10: 142500 | Q10: 141390 | R10: 141255
A11: Production | C11: 140580 | D11: 134980 | E11: 130555 | F11: 133375 | G11: 136215 | H11: 137375 | I11: 142075 | J11: 146320 | K11: 148870 | L11: 150435 | M11: 152015 | N11: 152670 | O11: 155450 | P11: 154525 | Q11: 151710 | R11: 148240
A13: Mining, quarrying & utilities | C13: 7360 | D13: 7610 | E13: 8055 | F13: 9080 | G13: 10285 | H13: 11020 | I13: 11125 | J13: 13070 | K13: 13620 | L13: 14330 | M13: 14655 | N13: 14965 | O13: 15355 | P13: 16085 | Q13: 15890 | R13: 15945
A14: Manufacturing | C14: 133220 | D14: 127370 | E14: 122500 | F14: 124295 | G14: 125930 | H14: 126355 | I14: 130140 | J14: 133250 | K14: 135250 | L14: 136105 | M14: 137360 | N14: 137705 | O14: 140095 | P14: 138440 | Q14: 135820 | R14: 132295
A16: Construction | C16: 289085 | D16: 274415 | E16: 262465 | F16: 263735 | G16: 257425 | H16: 266315 | I16: 284430 | J16: 301855 | K16: 319860 | L16: 331560 | M16: 343715 | N16: 351250 | O16: 359710 | P16: 374980 | Q16: 377585 | R16: 380195
A17: Motor Trade, Wholesale and Retail | C17: 367535 | D17: 359380 | E17: 357435 | F17: 360920 | G17: 358170 | H17: 362685 | I17: 368600 | J17: 369840 | K17: 375290 | L17: 380230 | M17: 389105 | N17: 387040 | O17: 406420 | P17: 413825 | Q17: 402165 | R17: 398210
A19: Motor trades | C19: 67560 | D19: 66595 | E19: 66475 | F19: 68045 | G19: 67600 | H19: 68420 | I19: 71885 | J19: 73460 | K19: 75075 | L19: 75755 | M19: 77200 | N19: 76910 | O19: 78995 | P19: 81125 | Q19: 80860 | R19: 81630
A20: Wholesale | C20: 107375 | D20: 104465 | E20: 103570 | F20: 103595 | G20: 103010 | H20: 103910 | I20: 104265 | J20: 103985 | K20: 103415 | L20: 102560 | M20: 103145 | N20: 101330 | O20: 106740 | P20: 108455 | Q20: 104310 | R20: 101965
A21: Retail | C21: 192600 | D21: 188320 | E21: 187390 | F21: 189280 | G21: 187560 | H21: 190355 | I21: 192445 | J21: 192395 | K21: 196800 | L21: 201915 | M21: 208760 | N21: 208800 | O21: 220685 | P21: 224245 | Q21: 216995 | R21: 214615
A23: Transport & storage (inc. postal) | C23: 71180 | D23: 67530 | E23: 65940 | F23: 67030 | G23: 67485 | H23: 72070 | I23: 82580 | J23: 92860 | K23: 109290 | L23: 108985 | M23: 111360 | N23: 123075 | O23: 138405 | P23: 138160 | Q23: 128600 | R23: 116875
A24: Accommodation & food services | C24: 134220 | D24: 129740 | E24: 127205 | F24: 131095 | G24: 128925 | H24: 132810 | I24: 146480 | J24: 148020 | K24: 150290 | L24: 153105 | M24: 157035 | N24: 161695 | O24: 167005 | P24: 175180 | Q24: 174830 | R24: 173515
A25: Information & communication | C25: 148690 | D25: 144890 | E25: 147465 | F25: 158775 | G25: 165500 | H25: 179120 | I25: 192725 | J25: 206960 | K25: 217025 | L25: 219150 | M25: 226215 | N25: 225745 | O25: 212960 | P25: 196090 | Q25: 187360 | R25: 187760
... A35: Total | C35: 2152400 | D35: 2100370 | E35: 2080860 | F35: 2149190 | G35: 2167580 | H35: 2263645 | I35: 2449415 | J35: 2554510 | K35: 2668810 | L35: 2669440 | M35: 2718435 | N35: 2749700 | O35: 2765150 | P35: 2767700 | Q35: 2726830 | R35: 2724770
A37: Percentage change | C37: -0.024173016 | D37: -0.009288836 | E37: +3.3% | F37: +0.9% | G37: +4.4% | H37: +8.2% | I37: +4.3% | J37: +4.5% | K37: 0.00023606027 | L37: +1.8% | M37: +1.2% | N37: +0.6% | O37: 0.00092219229 | P37: -0.014766774 | Q37: -0.00075545597
A38: Table 13 - Number of VAT and/or PAYE based enterprises by legal status, broad industry group and turnover sizebands (£000's) [note 1] [note 2] [note 3] [note 4 ] [note 6] [note 7]
A39: This worksheet contains one table
A40: Units: Counts (control rounded to base 5)
B41: 1 - Company (incl. Building Society) | M41: 2 - Sole Proprietor | X41: 3 - Partnership | AI41: 4 - Public Corporation/Nationalised Body | AT41: 5 - Central Government | BE41: 6 - Local Authority | BP41: 7 - Non-profit Body or Mutual Association | CA41: Total
C42: 0-49 | D42: 50-99 | E42: 100-249 | F42: 250-499 | G42: 500-999 | H42: 1000-1999 | I42: 2000-4999 | J42: 5000-9999 | K42: 10000-49999 | L42: 50000+ | M42: Total | N42: 0-49 | O42: 50-99 | P42: 100-249 | Q42: 250-499 | R42: 500-999 | S42: 1000-1999 | T42: 2000-4999 | U42: 5000-9999 | V42: 10000-49999 | W42: 50000+ | X42: Total | Y42: 0-49 | Z42: 50-99 | AA42: 100-249 | AB42: 250-499 | AC42: 500-999 | AD42: 1000-1999 | AE42: 2000-4999 | AF42: 5000-9999 | AG42: 10000-49999 | AH42: 50000+ | AI42: Total | AJ42: 0-49 | AK42: 50-99 | AL42: 100-249 | AM42: 250-499 | AN42: 500-999 | AO42: 1000-1999 | AP42: 2000-4999 | AQ42: 5000-9999 | AR42: 10000-49999 | AS42: 50000+ | AT42: Total | AU42: 0-49 | AV42: 50-99 | AW42: 100-249 | AX42: 250-499 | AY42: 500-999 | AZ42: 1000-1999 | BA42: 2000-4999 | BB42: 5000-9999 | BC42: 10000-49999 | BD42: 50000+ | BE42: Total | BF42: 0-49 | BG42: 50-99 | BH42: 100-249 | BI42: 250-499 | BJ42: 500-999 | BK42: 1000-1999 | BL42: 2000-4999 | BM42: 5000-9999 | BN42: 10000-49999 | BO42: 50000+ | BP42: Total | BQ42: 0-49 | BR42: 50-99 | BS42: 100-249 | BT42: 250-499 | BU42: 500-999 | BV42: 1000-1999 | BW42: 2000-4999 | BX42: 5000-9999 | BY42: 10000-49999 | BZ42: 50000+ | CA42: Total | CB42: 0-49 | CC42: 50-99 | CD42: 100-249 | CE42: 250-499 | CF42: 500-999 | CG42: 1000-1999 | CH42: 2000-4999 | CI42: 5000-9999 | CJ42: 10000-49999 | CK42: 50000+ | CL42: Total
A43: 01-03 : Agriculture, forestry & fishing | C43: 3395 | D43: 3780 | E43: 5750 | F43: 3625 | G43: 3220 | H43: 2400 | I43: 1615 | J43: 525 | K43: 310 | L43: 50 | M43: 24670 | N43: 23635 | O43: 13250 | P43: 10070 | Q43: 3675 | R43: 1625 | S43: 480 | T43: 175 | U43: 30 | V43: 5 | W43: 0 | X43: 52945 | Y43: 17340 | Z43: 8710 | AA43: 15825 | AB43: 10155 | AC43: 6725 | AD43: 2990 | AE43: 940 | AF43: 130 | AG43: 45 | AH43: 0 | AI43: 62860 | AJ43: 0 | AK43: 0 | AL43: 0 | AM43: 0 | AN43: 0 | AO43: 0 | AP43: 0 | AQ43: 0 | AR43: 0 | AS43: 0 | AT43: 0 | AU43: 0 | AV43: 0 | AW43: 0 | AX43: 0 | AY43: 0 | AZ43: 0 | BA43: 0 | BB43: 0 | BC43: 0 | BD43: 5 | BE43: 5 | BF43: 0 | BG43: 0 | BH43: 0 | BI43: 0 | BJ43: 0 | BK43: 0 | BL43: 0 | BM43: 0 | BN43: 0 | BO43: 0 | BP43: 0 | BQ43: 180 | BR43: 135 | BS43: 195 | BT43: 110 | BU43: 85 | BV43: 35 | BW43: 25 | BX43: 5 | BY43: 5 | BZ43: 0 | CA43: 775 | CB43: 44550 | CC43: 25875 | CD43: 31840 | CE43: 17565 | CF43: 11655 | CG43: 5905 | CH43: 2755 | CI43: 690 | CJ43: 365 | CK43: 55 | CL43: 141255
A44: 05-39 : Production | C44: 12495 | D44: 20800 | E44: 29805 | F44: 16440 | G44: 13880 | H44: 10775 | I44: 9860 | J44: 4685 | K44: 5195 | L44: 1805 | M44: 125740 | N44: 3965 | O44: 4205 | P44: 6380 | Q44: 1520 | R44: 460 | S44: 110 | T44: 35 | U44: 5 | V44: 0 | W44: 0 | X44: 16680 | Y44: 820 | Z44: 955 | AA44: 1820 | AB44: 955 | AC44: 440 | AD44: 180 | AE44: 80 | AF44: 25 | AG44: 20 | AH44: 5 | AI44: 5300 | AJ44: 0 | AK44: 0 | AL44: 0 | AM44: 0 | AN44: 0 | AO44: 0 | AP44: 5 | AQ44: 0 | AR44: 0 | AS44: 5 | AT44: 10 | AU44: 0 | AV44: 0 | AW44: 0 | AX44: 0 | AY44: 0 | AZ44: 0 | BA44: 0 | BB44: 0 | BC44: 0 | BD44: 10 | BE44: 10 | BF44: 5 | BG44: 10 | BH44: 10 | BI44: 5 | BJ44: 10 | BK44: 5 | BL44: 0 | BM44: 0 | BN44: 5 | BO44: 0 | BP44: 50 | BQ44: 85 | BR44: 80 | BS44: 120 | BT44: 75 | BU44: 50 | BV44: 25 | BW44: 10 | BX44: 0 | BY44: 5 | BZ44: 0 | CA44: 450 | CB44: 17370 | CC44: 26050 | CD44: 38135 | CE44: 18995 | CF44: 14840 | CG44: 11095 | CH44: 9990 | CI44: 4715 | CJ44: 5225 | CK44: 1825 | CL44: 148240
A45: 41-43 : Construction | C45: 22160 | D45: 56095 | E45: 103515 | F45: 53750 | G45: 33820 | H45: 18850 | I45: 12560 | J45: 4155 | K45: 3180 | L45: 635 | M45: 308720 | N45: 8750 | O45: 15895 | P45: 24630 | Q45: 7145 | R45: 1910 | S45: 345 | T45: 75 | U45: 5 | V45: 5 | W45: 0 | X45: 58760 | Y45: 1635 | Z45: 2285 | AA45: 4690 | AB45: 1930 | AC45: 1025 | AD45: 315 | AE45: 105 | AF45: 30 | AG45: 30 | AH45: 25 | AI45: 12070 | AJ45: 0 | AK45: 0 | AL45: 0 | AM45: 0 | AN45: 0 | AO45: 0 | AP45: 0 | AQ45: 0 | AR45: 0 | AS45: 0 | AT45: 0 | AU45: 0 | AV45: 0 | AW45: 0 | AX45: 0 | AY45: 0 | AZ45: 0 | BA45: 0 | BB45: 0 | BC45: 0 | BD45: 0 | BE45: 0 | BF45: 5 | BG45: 0 | BH45: 0 | BI45: 5 | BJ45: 0 | BK45: 5 | BL45: 0 | BM45: 0 | BN45: 0 | BO45: 0 | BP45: 15 | BQ45: 190 | BR45: 110 | BS45: 140 | BT45: 70 | BU45: 60 | BV45: 25 | BW45: 25 | BX45: 5 | BY45: 10 | BZ45: 0 | CA45: 635 | CB45: 32740 | CC45: 74385 | CD45: 132975 | CE45: 62900 | CF45: 36815 | CG45: 19540 | CH45: 12765 | CI45: 4195 | CJ45: 3225 | CK45: 660 | CL45: 380200
A46: 45 : Motor trades | C46: 3315 | D46: 9180 | E46: 17235 | F46: 11680 | G46: 7280 | H46: 4430 | I46: 3425 | J46: 1325 | K46: 1260 | L46: 435 | M46: 59565 | N46: 2045 | O46: 3135 | P46: 7120 | Q46: 2665 | R46: 1050 | S46: 395 | T46: 130 | U46: 20 | V46: 10 | W46: 0 | X46: 16570 | Y46: 330 | Z46: 595 | AA46: 1895 | AB46: 1335 | AC46: 700 | AD46: 330 | AE46: 190 | AF46: 40 | AG46: 25 | AH46: 0 | AI46: 5440 | AJ46: 0 | AK46: 0 | AL46: 0 | AM46: 0 | AN46: 0 | AO46: 0 | AP46: 0 | AQ46: 0 | AR46: 0 | AS46: 0 | AT46: 0 | AU46: 0 | AV46: 0 | AW46: 0 | AX46: 0 | AY46: 0 | AZ46: 0 | BA46: 0 | BB46: 0 | BC46: 0 | BD46: 0 | BE46: 0 | BF46: 0 | BG46: 0 | BH46: 0 | BI46: 0 | BJ46: 0 | BK46: 0 | BL46: 0 | BM46: 0 | BN46: 0 | BO46: 0 | BP46: 0 | BQ46: 10 | BR46: 15 | BS46: 20 | BT46: 10 | BU46: 0 | BV46: 0 | BW46: 0 | BX46: 0 | BY46: 0 | BZ46: 0 | CA46: 55 | CB46: 5700 | CC46: 12925 | CD46: 26270 | CE46: 15690 | CF46: 9030 | CG46: 5155 | CH46: 3745 | CI46: 1385 | CJ46: 1295 | CK46: 435 | CL46: 81630
A47: 46 : Wholesale | C47: 9860 | D47: 7860 | E47: 16475 | F47: 12840 | G47: 11635 | H47: 9650 | I47: 9700 | J47: 4995 | K47: 5195 | L47: 1650 | M47: 89860 | N47: 2110 | O47: 1665 | P47: 2235 | Q47: 985 | R47: 605 | S47: 305 | T47: 130 | U47: 20 | V47: 5 | W47: 0 | X47: 8060 | Y47: 560 | Z47: 485 | AA47: 965 | AB47: 605 | AC47: 510 | AD47: 375 | AE47: 210 | AF47: 90 | AG47: 45 | AH47: 5 | AI47: 3850 | AJ47: 0 | AK47: 0 | AL47: 0 | AM47: 0 | AN47: 0 | AO47: 0 | AP47: 0 | AQ47: 0 | AR47: 0 | AS47: 0 | AT47: 0 | AU47: 0 | AV47: 0 | AW47: 0 | AX47: 0 | AY47: 0 | AZ47: 0 | BA47: 0 | BB47: 0 | BC47: 0 | BD47: 0 | BE47: 0 | BF47: 0 | BG47: 0 | BH47: 0 | BI47: 0 | BJ47: 0 | BK47: 0 | BL47: 0 | BM47: 0 | BN47: 0 | BO47: 0 | BP47: 0 | BQ47: 35 | BR47: 25 | BS47: 25 | BT47: 40 | BU47: 20 | BV47: 10 | BW47: 10 | BX47: 5 | BY47: 15 | BZ47: 5 | CA47: 190 | CB47: 12565 | CC47: 10035 | CD47: 19700 | CE47: 14470 | CF47: 12770 | CG47: 10340 | CH47: 10050 | CI47: 5110 | CJ47: 5260 | CK47: 1660 | CL47: 101960
A48: 47 : Retail | C48: 16290 | D48: 22465 | E48: 47495 | F48: 31060 | G48: 22095 | H48: 12070 | I48: 7050 | J48: 2235 | K48: 1470 | L48: 475 | M48: 162705 | N48: 4310 | O48: 5850 | P48: 13940 | Q48: 7055 | R48: 2945 | S48: 640 | T48: 165 | U48: 30 | V48: 10 | W48: 0 | X48: 34945 | Y48: 990 | Z48: 1535 | AA48: 5070 | AB48: 4320 | AC48: 2525 | AD48: 920 | AE48: 300 | AF48: 75 | AG48: 30 | AH48: 0 | AI48: 15765 | AJ48: 0 | AK48: 0 | AL48: 0 | AM48: 0 | AN48: 0 | AO48: 0 | AP48: 0 | AQ48: 0 | AR48: 0 | AS48: 0 | AT48: 0 | AU48: 0 | AV48: 0 | AW48: 0 | AX48: 0 | AY48: 0 | AZ48: 0 | BA48: 0 | BB48: 0 | BC48: 0 | BD48: 0 | BE48: 0 | BF48: 0 | BG48: 0 | BH48: 0 | BI48: 0 | BJ48: 0 | BK48: 0 | BL48: 0 | BM48: 0 | BN48: 0 | BO48: 0 | BP48: 0 | BQ48: 145 | BR48: 185 | BS48: 435 | BT48: 220 | BU48: 125 | BV48: 50 | BW48: 20 | BX48: 10 | BY48: 5 | BZ48: 5 | CA48: 1200 | CB48: 21735 | CC48: 30035 | CD48: 66940 | CE48: 42655 | CF48: 27690 | CG48: 13680 | CH48: 7535 | CI48: 2350 | CJ48: 1515 | CK48: 480 | CL48: 214615
A49: 49-53 : Transport & Storage (inc. postal) | C49: 11110 | D49: 19820 | E49: 24890 | F49: 7890 | G49: 6175 | H49: 4245 | I49: 3430 | J49: 1490 | K49: 1475 | L49: 505 | M49: 81030 | N49: 20170 | O49: 5615 | P49: 4280 | Q49: 1265 | R49: 525 | S49: 215 | T49: 55 | U49: 10 | V49: 0 | W49: 0 | X49: 32135 | Y49: 385 | Z49: 445 | AA49: 985 | AB49: 610 | AC49: 345 | AD49: 175 | AE49: 95 | AF49: 10 | AG49: 5 | AH49: 0 | AI49: 3055 | AJ49: 0 | AK49: 0 | AL49: 5 | AM49: 5 | AN49: 0 | AO49: 0 | AP49: 0 | AQ49: 5 | AR49: 20 | AS49: 25 | AT49: 60 | AU49: 0 | AV49: 0 | AW49: 0 | AX49: 0 | AY49: 0 | AZ49: 0 | BA49: 0 | BB49: 0 | BC49: 5 | BD49: 5 | BE49: 10 | BF49: 5 | BG49: 0 | BH49: 0 | BI49: 0 | BJ49: 0 | BK49: 0 | BL49: 0 | BM49: 0 | BN49: 5 | BO49: 5 | BP49: 15 | BQ49: 145 | BR49: 110 | BS49: 120 | BT49: 65 | BU49: 55 | BV49: 30 | BW49: 30 | BX49: 10 | BY49: 5 | BZ49: 0 | CA49: 570 | CB49: 31815 | CC49: 25990 | CD49: 30280 | CE49: 9835 | CF49: 7100 | CG49: 4665 | CH49: 3610 | CI49: 1525 | CJ49: 1515 | CK49: 540 | CL49: 116875
A50: 55-56 : Accommodation & food services | C50: 10375 | D50: 21860 | E50: 48430 | F50: 24210 | G50: 14275 | H50: 6515 | I50: 3295 | J50: 1135 | K50: 845 | L50: 210 | M50: 131150 | N50: 815 | O50: 5970 | P50: 12590 | Q50: 3545 | R50: 915 | S50: 195 | T50: 35 | U50: 10 | V50: 0 | W50: 0 | X50: 24075 | Y50: 590 | Z50: 1420 | AA50: 6130 | AB50: 2985 | AC50: 1280 | AD50: 375 | AE50: 100 | AF50: 15 | AG50: 0 | AH50: 0 | AI50: 12895 | AJ50: 0 | AK50: 0 | AL50: 0 | AM50: 0 | AN50: 0 | AO50: 0 | AP50: 0 | AQ50: 0 | AR50: 0 | AS50: 0 | AT50: 0 | AU50: 0 | AV50: 0 | AW50: 5 | AX50: 5 | AY50: 0 | AZ50: 0 | BA50: 0 | BB50: 0 | BC50: 0 | BD50: 0 | BE50: 10 | BF50: 0 | BG50: 0 | BH50: 0 | BI50: 0 | BJ50: 0 | BK50: 0 | BL50: 5 | BM50: 0 | BN50: 0 | BO50: 0 | BP50: 5 | BQ50: 540 | BR50: 860 | BS50: 2395 | BT50: 1210 | BU50: 265 | BV50: 55 | BW50: 30 | BX50: 15 | BY50: 10 | BZ50: 0 | CA50: 5380 | CB50: 12320 | CC50: 30110 | CD50: 69550 | CE50: 31955 | CF50: 16735 | CG50: 7140 | CH50: 3465 | CI50: 1175 | CJ50: 855 | CK50: 210 | CL50: 173515
A51: 58-63 : Information & communication | C51: 28415 | D51: 46480 | E51: 63260 | F51: 15715 | G51: 9115 | H51: 6070 | I51: 4955 | J51: 2110 | K51: 2050 | L51: 740 | M51: 178910 | N51: 2150 | O51: 2305 | P51: 1965 | Q51: 280 | R51: 105 | S51: 15 | T51: 15 | U51: 5 | V51: 0 | W51: 0 | X51: 6840 | Y51: 295 | Z51: 225 | AA51: 315 | AB51: 100 | AC51: 40 | AD51: 20 | AE51: 10 | AF51: 0 | AG51: 5 | AH51: 0 | AI51: 1010 | AJ51: 0 | AK51: 0 | AL51: 0 | AM51: 0 | AN51: 0 | AO51: 0 | AP51: 0 | AQ51: 0 | AR51: 0 | AS51: 5 | AT51: 5 | AU51: 0 | AV51: 0 | AW51: 0 | AX51: 0 | AY51: 0 | AZ51: 0 | BA51: 0 | BB51: 5 | BC51: 0 | BD51: 0 | BE51: 5 | BF51: 0 | BG51: 0 | BH51: 0 | BI51: 0 | BJ51: 0 | BK51: 0 | BL51: 0 | BM51: 0 | BN51: 0 | BO51: 0 | BP51: 0 | BQ51: 165 | BR51: 200 | BS51: 280 | BT51: 150 | BU51: 95 | BV51: 50 | BW51: 25 | BX51: 10 | BY51: 10 | BZ51: 5 | CA51: 990 | CB51: 31025 | CC51: 49210 | CD51: 65820 | CE51: 16245 | CF51: 9355 | CG51: 6155 | CH51: 5005 | CI51: 2130 | CJ51: 2065 | CK51: 750 | CL51: 187760
A52: 64-66 : Finance & insurance | C52: 11300 | D52: 2015 | E52: 13215 | F52: 6215 | G52: 3965 | H52: 2165 | I52: 1545 | J52: 745 | K52: 1045 | L52: 810 | M52: 43020 | N52: 45 | O52: 35 | P52: 675 | Q52: 340 | R52: 120 | S52: 30 | T52: 5 | U52: 0 | V52: 0 | W52: 0 | X52: 1250 | Y52: 90 | Z52: 30 | AA52: 35 | AB52: 150 | AC52: 155 | AD52: 90 | AE52: 25 | AF52: 10 | AG52: 0 | AH52: 0 | AI52: 585 | AJ52: 0 | AK52: 0 | AL52: 0 | AM52: 0 | AN52: 0 | AO52: 0 | AP52: 0 | AQ52: 0 | AR52: 5 | AS52: 5 | AT52: 10 | AU52: 5 | AV52: 0 | AW52: 0 | AX52: 0 | AY52: 0 | AZ52: 0 | BA52: 0 | BB52: 0 | BC52: 5 | BD52: 5 | BE52: 15 | BF52: 0 | BG52: 0 | BH52: 0 | BI52: 0 | BJ52: 0 | BK52: 0 | BL52: 0 | BM52: 0 | BN52: 0 | BO52: 0 | BP52: 0 | BQ52: 13350 | BR52: 110 | BS52: 135 | BT52: 90 | BU52: 95 | BV52: 45 | BW52: 30 | BX52: 15 | BY52: 20 | BZ52: 25 | CA52: 13915 | CB52: 24790 | CC52: 2190 | CD52: 14060 | CE52: 6795 | CF52: 4335 | CG52: 2330 | CH52: 1605 | CI52: 770 | CJ52: 1075 | CK52: 845 | CL52: 58795
A53: 68 : Property | C53: 13865 | D53: 24245 | E53: 28455 | F53: 13195 | G53: 7015 | H53: 3645 | I53: 2020 | J53: 745 | K53: 625 | L53: 170 | M53: 93980 | N53: 3585 | O53: 1345 | P53: 2100 | Q53: 645 | R53: 245 | S53: 80 | T53: 45 | U53: 10 | V53: 5 | W53: 0 | X53: 8060 | Y53: 5705 | Z53: 2495 | AA53: 2270 | AB53: 1045 | AC53: 470 | AD53: 190 | AE53: 80 | AF53: 20 | AG53: 30 | AH53: 5 | AI53: 12310 | AJ53: 0 | AK53: 0 | AL53: 0 | AM53: 0 | AN53: 0 | AO53: 0 | AP53: 0 | AQ53: 0 | AR53: 15 | AS53: 10 | AT53: 25 | AU53: 0 | AV53: 0 | AW53: 0 | AX53: 5 | AY53: 0 | AZ53: 0 | BA53: 0 | BB53: 0 | BC53: 0 | BD53: 0 | BE53: 5 | BF53: 5 | BG53: 0 | BH53: 5 | BI53: 0 | BJ53: 0 | BK53: 0 | BL53: 0 | BM53: 0 | BN53: 0 | BO53: 0 | BP53: 10 | BQ53: 1150 | BR53: 705 | BS53: 725 | BT53: 330 | BU53: 215 | BV53: 135 | BW53: 80 | BX53: 50 | BY53: 65 | BZ53: 50 | CA53: 3505 | CB53: 24310 | CC53: 28790 | CD53: 33555 | CE53: 15220 | CF53: 7945 | CG53: 4050 | CH53: 2225 | CI53: 825 | CJ53: 740 | CK53: 235 | CL53: 117895
A54: 69-75 : Professional, scientific & technical | C54: 50445 | D54: 80305 | E54: 139065 | F54: 40245 | G54: 20660 | H54: 12635 | I54: 8730 | J54: 3470 | K54: 3060 | L54: 910 | M54: 359525 | N54: 7820 | O54: 9875 | P54: 21805 | Q54: 5380 | R54: 1805 | S54: 560 | T54: 135 | U54: 15 | V54: 0 | W54: 0 | X54: 47395 | Y54: 1045 | Z54: 1110 | AA54: 2155 | AB54: 1320 | AC54: 950 | AD54: 560 | AE54: 285 | AF54: 80 | AG54: 55 | AH54: 20 | AI54: 7580 | AJ54: 0 | AK54: 0 | AL54: 0 | AM54: 0 | AN54: 0 | AO54: 5 | AP54: 5 | AQ54: 0 | AR54: 0 | AS54: 5 | AT54: 15 | AU54: 5 | AV54: 0 | AW54: 5 | AX54: 5 | AY54: 5 | AZ54: 0 | BA54: 5 | BB54: 5 | BC54: 5 | BD54: 0 | BE54: 35 | BF54: 0 | BG54: 0 | BH54: 0 | BI54: 0 | BJ54: 0 | BK54: 0 | BL54: 0 | BM54: 0 | BN54: 0 | BO54: 5 | BP54: 5 | BQ54: 280 | BR54: 505 | BS54: 830 | BT54: 505 | BU54: 400 | BV54: 245 | BW54: 160 | BX54: 65 | BY54: 60 | BZ54: 10 | CA54: 3060 | CB54: 59595 | CC54: 91795 | CD54: 163860 | CE54: 47455 | CF54: 23820 | CG54: 14005 | CH54: 9320 | CI54: 3635 | CJ54: 3180 | CK54: 950 | CL54: 417615
... A60: Total | C60: 241975 | D60: 406995 | E60: 667585 | F60: 288150 | G60: 186790 | H60: 113280 | I60: 82530 | J60: 32480 | K60: 29885 | L60: 9455 | M60: 2059125 | N60: 89075 | O60: 90575 | P60: 135945 | Q60: 54045 | R60: 20310 | S60: 5170 | T60: 1365 | U60: 200 | V60: 55 | W60: 0 | X60: 396740 | Y60: 33830 | Z60: 22800 | AA60: 47780 | AB60: 28585 | AC60: 18650 | AD60: 9670 | AE60: 4920 | AF60: 805 | AG60: 370 | AH60: 60 | AI60: 167470 | AJ60: 0 | AK60: 0 | AL60: 5 | AM60: 5 | AN60: 5 | AO60: 10 | AP60: 10 | AQ60: 5 | AR60: 55 | AS60: 70 | AT60: 165 | AU60: 105 | AV60: 60 | AW60: 115 | AX60: 140 | AY60: 210 | AZ60: 380 | BA60: 695 | BB60: 620 | BC60: 755 | BD60: 385 | BE60: 3465 | BF60: 360 | BG60: 4890 | BH60: 1625 | BI60: 480 | BJ60: 275 | BK60: 395 | BL60: 430 | BM60: 225 | BN60: 230 | BO60: 145 | BP60: 9055 | BQ60: 23320 | BR60: 12220 | BS60: 21610 | BT60: 13170 | BU60: 8420 | BV60: 4635 | BW60: 2945 | BX60: 1100 | BY60: 1000 | BZ60: 325 | CA60: 88745 | CB60: 388665 | CC60: 537540 | CD60: 874665 | CE60: 384575 | CF60: 234660 | CG60: 133540 | CH60: 92895 | CI60: 35435 | CJ60: 32350 | CK60: 10440 | CL60: 2724765
A62: AGR | B62: =((R35-C35)/C35)*(1/16)*100 -> 1.662011
A63: Monthly Growth rate | B63: =(1+B62)^(1/12)-1 -> 0.085011032
...
